Workbook
Name UPDATE: 'Data Sheet'!$E$1

Sheet Model Checks
A1: INFOSYS LTD - Model Checks & Audit Dashboard
A2: Green = pass; red = review. Checks are formula-driven and intended to catch linkage, assumption and valuation-consistency issues.
A4: Core Checks
A5: Check | B5: Result | C5: Status | D5: Comment
A6: Historical balance sheet balances | B6: =AND(HistoricalFS!C66:L66) -> TRUE | C6: =IF(B6,"PASS","REVIEW") -> PASS | D6: HistoricalFS check should be TRUE in every year
A7: Terminal growth below WACC | B7: ='Operating Drivers'!B47="PASS" -> TRUE | C7: =IF(B7,"PASS","REVIEW") -> PASS | D7: Terminal g must remain below WACC
A8: Terminal reinvestment formula | B8: =ABS('Operating Drivers'!B46-'Operating Drivers'!B44/'Operating Drivers'!B45)<0.000001 -> TRUE | C8: =IF(B8,"PASS","REVIEW") -> PASS | D8: Terminal reinvestment = g / terminal ROIC
A9: FY27 reinvestment formula | B9: =ABS('Operating Drivers'!B37-'Operating Drivers'!B34/'Operating Drivers'!B36)<0.000001 -> TRUE | C9: =IF(B9,"PASS","REVIEW") -> PASS | D9: Explicit reinvestment = growth / target ROIC
A10: DCF tax linked to normalized effective tax | B10: =ABS('DCF>'!F10-'Operating Drivers'!B38)<0.000001 -> TRUE | C10: =IF(B10,"PASS","REVIEW") -> PASS | D10: DCF FCFF tax should use the normalized 29.5% effective tax assumption.
A11: WACC tax shield rate separately defined | B11: =ABS(WACC!E28-'Operating Drivers'!B48)<0.000001 -> TRUE | C11: =IF(B11,"PASS","REVIEW") -> PASS | D11: WACC debt tax shield uses the separately defined marginal/statutory tax rate.
A12: DCF terminal discount uses 4.5 years | B12: =ABS(('DCF>'!D40/('DCF>'!D34))-1/(1+'DCF>'!F26)^4.5)<0.000001 -> TRUE | C12: =IF(B12,"PASS","REVIEW") -> PASS | D12: Mid-year explicit forecast ends at 4.5 years
A13: DCF base agrees with scenario base | B13: =ABS('DCF>'!D48-Scenarios!K4)<1 -> TRUE | C13: =IF(B13,"PASS","REVIEW") -> PASS | D13: Base scenario should reconcile to main DCF within ₹1/share
A14: Terminal value multiple check | B14: =ISNUMBER('DCF>'!D65) -> TRUE | C14: =IF(B14,"PASS","REVIEW") -> PASS | D14: Terminal-value implied EV/EBITDA is a diagnostic only; compare with the core-peer median and do not treat it as an exit-multiple input.
A15: No terminal growth error | B15: =Forecasting!R18="PASS" -> TRUE | C15: =IF(B15,"PASS","REVIEW") -> PASS | D15: Forecasting terminal-growth check should pass
A16: Forecast tax rate consistent across FY27-FY31 | B16: =AND('Operating Drivers'!B38='Operating Drivers'!C38,'Operating Drivers'!C38='Operating Drivers'!D38,'Operating Drivers'!D38='Operating Drivers'!E38,'Operating Drivers'!E38='Operating Drivers'!F38) -> TRUE | C16: =IF(B16,"PASS","REVIEW") -> PASS | D16: All explicit DCF forecast years use the normalized effective tax rate.
A17: Segment-weighted growth ties to top-down total (internal tie, not a guidance check) | B17: =ABS('Operating Drivers'!B29-'Operating Drivers'!B34)<0.001 -> TRUE | C17: =IF(B17,"PASS","REVIEW") -> PASS | D17: Internal segment-to-total tie: FY27 weighted segment growth is definitionally close to the top-down base growth because both derive from the same segment total. It does NOT test against company CC guidance (see Operating Drivers!D29 for that comparison, 2.458% model vs 2.25% guidance midpoint, ~21bps gap, shown for context but not wired into this dashboard).
A18: Segment FY27-FY31 links reconcile | B18: =SUMPRODUCT(ABS('Segment Profitability'!C3:C10-'Segment Forecast'!D3:D10))+SUMPRODUCT(ABS('Segment Profitability'!D3:D10-'Segment Forecast'!E3:E10))+SUMPRODUCT(ABS('Segment Profitability'!E3:E10-'Segment Forecast'!F3:F10))+SUMPRODUCT(ABS('Segment Profitability'!F3:F10-'Segment Forecast'!G3:G10))+SUMPRODUCT(ABS('Segment Profitability'!G3:G10-'Segment Forecast'!H3:H10))<0.01 -> TRUE | C18: =IF(B18,"PASS","REVIEW") -> PASS | D18: All forecast segment years must link to the matching year.
A19: All Other segment is linked | B19: =SUMPRODUCT(ABS('Segment Profitability'!C10:G10-'Segment Forecast'!D10:H10))<0.01 -> TRUE | C19: =IF(B19,"PASS","REVIEW") -> PASS | D19: All Other should not have a separate hardcoded growth engine.
A20: Weighted FY27 growth uses FY26 weights | B20: =ABS('Operating Drivers'!B29-SUMPRODUCT('Operating Drivers'!C21:C28,'Operating Drivers'!E21:E28)/SUM('Operating Drivers'!C21:C28))<0.000001 -> TRUE | C20: =IF(B20,"PASS","REVIEW") -> PASS | D20: Cross-check uses FY26 segment revenue weights.
A21: Corporate cost bridge anchored to FY26 normalization | B21: =ABS('Operating Drivers'!B41-('Segment Profitability'!B32-'Normalization Bridge'!B5)/'Segment Profitability'!B31)<0.000001 -> TRUE | C21: =IF(B21,"PASS","REVIEW") -> PASS | D21: FY26 normalized corporate/unallocated costs are explicit.
A22: Integrated EBIT bridge | B22: =SUMPRODUCT(ABS('Integrated Operating Model'!C8:G8-('Integrated Operating Model'!C5:G5-'Integrated Operating Model'!C7:G7)))<0.01 -> TRUE | C22: =IF(B22,"PASS","REVIEW") -> PASS | D22: Consolidated EBIT = segment operating income - corporate/unallocated costs.
A23: Integrated DCF terminal assumptions linked | B23: =AND('DCF Integration'!B8='Operating Drivers'!B44,'DCF Integration'!G8='Operating Drivers'!B44,'DCF Integration'!B9='Operating Drivers'!B45) -> TRUE | C23: =IF(B23,"PASS","REVIEW") -> PASS | D23: Integrated DCF terminal inputs have one source of truth.
A24: Integrated equity bridge | B24: =ABS('DCF Integration'!G19-('DCF Integration'!G15-'DCF Integration'!G18))<0.01 -> TRUE | C24: =IF(B24,"PASS","REVIEW") -> PASS | D24: Equity value = enterprise value - net debt.
A25: Integrated per-share bridge | B25: =ABS('DCF Integration'!G21-'DCF Integration'!G19/'DCF Integration'!G20)<0.01 -> TRUE | C25: =IF(B25,"PASS","REVIEW") -> PASS | D25: Intrinsic value/share recomputes from equity value and shares.
A26: Core peer median populated | B26: =AND(ISNUMBER('Comps Val'!O28),ISNUMBER('Comps Val'!P28),ISNUMBER('Comps Val'!Q28)) -> TRUE | C26: =IF(B26,"PASS","REVIEW") -> PASS | D26: Core peer set is separately identified from extended peers.
A27: Beta data freshness flagged | B27: =MAX('Beta - Regression'!B10:B114)>=DATE(2026,8,1) -> TRUE | C27: =IF(B27,"PASS","REVIEW") -> PASS | D27: Beta window runs through the last available weekly close before the 22-Aug-2026 valuation date; weekly series refreshed through the week of 18-Aug-2026 (last observation 16-Aug-2026).
A28: Key Outputs
A29: WACC | B29: =WACC!L45 -> 0.11593086
A30: DCF Value / Share | B30: ='DCF>'!D48 -> 796.21701
A31: Current Price | B31: ='DCF>'!D50 -> 1121
A32: Terminal Growth | B32: ='Operating Drivers'!B44 -> 0.03
A33: Terminal ROIC | B33: ='Operating Drivers'!B45 -> 0.4
A34: Terminal Reinvestment | B34: ='Operating Drivers'!B46 -> 0.075
A35: Scenario Range | B35: =TEXT(Scenarios!K3,"₹#,##0")&" to "&TEXT(Scenarios!K5,"₹#,##0") -> ₹715 to ₹910

Sheet Valuation Summary
A1: Infosys Equity Research — Valuation Summary
A2: Metric | B2: Output / Methodology
A3: Legacy DCF Value / Share | B3: ='DCF>'!D48 -> 796.21701
A4: Integrated DCF Value / Share | B4: ='DCF Integration'!G21 -> 796.21701
A5: DCF Center | B5: =AVERAGE(B3:B4) -> 796.21701
A6: Core EV / Revenue Value / Share | B6: ='Comps Val'!O37 -> 1202.9478
A7: Core EV / EBITDA Value / Share | B7: ='Comps Val'!P37 -> 1398.6938
A8: Core P / E Value / Share | B8: ='Comps Val'!Q37 -> 1515.0278
A9: Primary Comps Cross-Check | B9: =B7 -> 1398.6938
A10: DCF Weight | B10: 0.6
A11: Comps Weight | B11: 0.4
A12: Indicative Target Price | B12: =B5*B10+B9*B11 -> 1037.2077
A13: Current Share Price | B13: ='DCF>'!D50 -> 1121
A14: Upside / (Downside) | B14: =B12/B13-1 -> -0.074747796
A15: Core Peer Set | B15: TCS, HCL Technologies, Wipro, Tech Mahindra, LTIMindtree
A16: Extended Peer Context | B16: Persistent Systems, Coforge, Mphasis, Hexaware
A17: Target methodology | B17: 60% DCF center / 40% core-peer EV/EBITDA. DCF is primary; comps are a market-based cross-check.
A18: Important limitation | B18: Beta: the 2-year weekly regression window is refreshed through the week of 18 Aug 2026 (last observation 16 Aug 2026, the last trading week before the valuation date); the beta-freshness model check passes.

Sheet Investment Thesis
A1: Infosys Equity Research — Investment Thesis
A2: Section | B2: Current conclusion
A3: Valuation | B3: DCF remains below the current market valuation, while trading comps imply materially higher values. The dispersion is a research question, not something to engineer away.
A4: Business outlook | B4: FY26 revenue was ₹178,650 crore; Q1 FY27 revenue was ₹48,211 crore and Q1 FY27 operating margin was 21.1%.
A5: Guidance | B5: FY27 constant-currency revenue growth guidance is 1.5%-3.0%.
A6: Catalyst 1 | B6: AI monetization and conversion of AI-led demand into higher-value services.
A7: Catalyst 2 | B7: Large-deal conversion and sustained transformation/cloud/data spending.
A8: Catalyst 3 | B8: Productivity and utilization improvements supporting margins.
A9: Risk 1 | B9: AI pricing pressure or automation may outpace new AI revenue.
A10: Risk 2 | B10: Weak discretionary IT spending and macro uncertainty.
A11: Risk 3 | B11: Communications and Hi-Tech remain more exposed to sector-specific pressure.
A12: Key valuation drivers | B12: Revenue growth, EBIT margin, WACC, terminal growth and terminal ROIC.
A13: What would change the view | B13: A sustained change in growth, margins, deal conversion or AI monetization would materially change intrinsic value.
A14: Methodology | B14: DCF uses FCFF; integrated DCF is bottom-up from segment operating income less normalized corporate/unallocated costs; terminal reinvestment = terminal growth / terminal ROIC; core trading comps provide the primary market cross-check.
A15: Legacy DCF Value / Share | B15: ='DCF>'!D48 -> 796.21701
A16: Integrated DCF Value / Share | B16: ='DCF Integration'!G21 -> 796.21701
A17: DCF Center | B17: ='Valuation Summary'!B5 -> 796.21701
A18: Core EV/EBITDA Cross-Check | B18: ='Valuation Summary'!B9 -> 1398.6938
A19: Indicative Target Price | B19: ='Valuation Summary'!B12 -> 1037.2077
A20: Current Share Price | B20: ='Valuation Summary'!B13 -> 1121
A21: Upside / (Downside) | B21: ='Valuation Summary'!B14 -> -0.074747796
A22: Indicative View | B22: HOLD / NEUTRAL — low conviction; DCF is below market while core-peer multiples provide a higher valuation cross-check.
A23: Target Price Method | B23: 60% DCF center + 40% core-peer EV/EBITDA. Core peers are used as the primary market cross-check; extended peers remain contextual.

Sheet Legacy vs Integrated
A1: Legacy DCF vs Integrated DCF
A2: Metric | B2: Legacy DCF | C2: Integrated DCF | D2: Difference | E2: Audit interpretation | F2: Status
A3: WACC | B3: ='DCF>'!D31 -> 0.11593086 | C3: ='DCF Integration'!G5 -> 0.11593086 | D3: =C3-B3 -> 0 | E3: Compare after recalculation. Any remaining gap should be attributable to the top-down vs. bottom-up forecast methodology, not broken year links. | F3: =IF(ABS(D3)<0.0005,"CONSISTENT","REVIEW: WACC inputs diverge") -> CONSISTENT
A4: Terminal Growth | B4: ='DCF>'!F25 -> 0.03 | C4: ='DCF Integration'!G8 -> 0.03 | D4: =C4-B4 -> 0 | E4: Compare after recalculation. Any remaining gap should be attributable to the top-down vs. bottom-up forecast methodology, not broken year links. | F4: =IF(ABS(D4)<0.0005,"CONSISTENT","REVIEW: terminal growth inputs diverge") -> CONSISTENT
A5: Terminal Value | B5: ='DCF>'!D34 -> 339178.39 | C5: ='DCF Integration'!G13 -> 339178.39 | D5: =C5-B5 -> 0 | E5: Compare after recalculation. Any remaining gap should be attributable to the top-down vs. bottom-up forecast methodology, not broken year links. | F5: =IF(ABS(D5/B5)<0.05,"CONSISTENT (within 5%)","REVIEW: methodology gap >5% - see interpretation") -> CONSISTENT (within 5%)
A6: Enterprise Value | B6: ='DCF>'!D41 -> 310087.82 | C6: ='DCF Integration'!G15 -> 310087.82 | D6: =C6-B6 -> 0 | E6: Compare after recalculation. Any remaining gap should be attributable to the top-down vs. bottom-up forecast methodology, not broken year links. | F6: =IF(ABS(D6/B6)<0.05,"CONSISTENT (within 5%)","REVIEW: methodology gap >5% - see interpretation") -> CONSISTENT (within 5%)
A7: Equity Value | B7: ='DCF>'!D45 -> 323112.82 | C7: ='DCF Integration'!G19 -> 323112.82 | D7: =C7-B7 -> 0 | E7: Compare after recalculation. Any remaining gap should be attributable to the top-down vs. bottom-up forecast methodology, not broken year links. | F7: =IF(ABS(D7/B7)<0.05,"CONSISTENT (within 5%)","REVIEW: methodology gap >5% - see interpretation") -> CONSISTENT (within 5%)
A8: Intrinsic Value / Share | B8: ='DCF>'!D48 -> 796.21701 | C8: ='DCF Integration'!G21 -> 796.21701 | D8: =C8-B8 -> 0 | E8: Compare after recalculation. Any remaining gap should be attributable to the top-down vs. bottom-up forecast methodology, not broken year links. | F8: =IF(ABS(D8/B8)<0.05,"CONSISTENT (within 5%)","REVIEW: methodology gap >5% - see interpretation") -> CONSISTENT (within 5%)
A9: Current Share Price | B9: ='DCF>'!D50 -> 1121 | C9: ='DCF Integration'!G23 -> 1121 | D9: =C9-B9 -> 0 | E9: Compare after recalculation. Any remaining gap should be attributable to the top-down vs. bottom-up forecast methodology, not broken year links. | F9: =IF(ABS(D9)<0.01,"CONSISTENT","REVIEW: share price inputs diverge") -> CONSISTENT
A11: Forecast Comparison
A12: Metric | B12: Legacy Forecast | C12: Integrated Forecast | D12: Difference | E12: Interpretation | F12: Status
A13: Metric | B13: FY27E | C13: FY28E | D13: FY29E | E13: FY30E | F13: FY31E
A14: Legacy Revenue (Rs Cr) | B14: =Forecasting!R5 -> 183041.22 | C14: =Forecasting!S5 -> 187795.96 | D14: =Forecasting!T5 -> 192927.49 | E14: =Forecasting!U5 -> 198458.63 | F14: =Forecasting!V5 -> 204412.39
A15: Integrated (Segment) Revenue (Rs Cr) | B15: ='Segment Profitability'!C31 -> 183041.22 | C15: ='Segment Profitability'!D31 -> 187795.96 | D15: ='Segment Profitability'!E31 -> 192927.49 | E15: ='Segment Profitability'!F31 -> 198458.63 | F15: ='Segment Profitability'!G31 -> 204412.39
A16: Revenue Difference (%) | B16: =B15/B14-1 -> 0 | C16: =C15/C14-1 -> 0 | D16: =D15/D14-1 -> 0 | E16: =E15/E14-1 -> 0 | F16: =F15/F14-1 -> 0
A18: Legacy EBIT (Rs Cr) | B18: =Forecasting!R7 -> 38384.84 | C18: =Forecasting!S7 -> 39524.433 | D18: =Forecasting!T7 -> 40801.562 | E18: =Forecasting!U7 -> 42094.066 | F18: =Forecasting!V7 -> 43391.96
A19: Integrated (Segment) Operating Income (Rs Cr) | B19: ='Segment Profitability'!C32 -> 43407.331 | C19: ='Segment Profitability'!D32 -> 44677.39 | D19: ='Segment Profitability'!E32 -> 46095.324 | E19: ='Segment Profitability'!F32 -> 47539.598 | F19: ='Segment Profitability'!G32 -> 49000.857
A20: EBIT Difference (%) | B20: =B19/B18-1 -> 0.1308457 | C20: =C19/C18-1 -> 0.13037397 | D20: =D19/D18-1 -> 0.1297441 | E20: =E19/E18-1 -> 0.12936578 | F20: =F19/F18-1 -> 0.12926122
A22: Interpretation: the integrated (bottom-up) DCF uses the FY27-FY31 segment links and an explicit corporate/unallocable cost bridge anchored to FY26 normalized EBIT. Because the top-down (Legacy) build takes its revenue growth and EBIT margin from the same segment engine, and both builds now apply the terminal (1+g) convention consistently, the two builds reconcile to the same value (~Rs 796/share). This is an internal build-integrity check, not two independent valuations. Segment operating margin is not treated as consolidated EBIT until the corporate-cost bridge is applied.

Sheet Audit Summary
A1: Infosys Equity Research Model -- Methodology & Audit Notes
A3: Purpose | B3: Methodology and QA reference for the Infosys Equity Research Model
A4: DCF forecast tax rate | B4: 29.5% normalized effective tax rate (FCFF)
A5: WACC debt tax shield rate | B5: 25.17% marginal/statutory rate (Sec. 115BAA) -- kept distinct from the 29.5% effective rate by design
A6: Terminal growth | B6: 3.0% base case (2.5% bear / 3.5% bull)
A7: Terminal ROIC | B7: 40.0% base case (35% bear / 45% bull) -- normalizes down from FY26 actual ROIC
A8: Terminal reinvestment | B8: Terminal growth / terminal ROIC = 7.5%, formula-linked, not a fixed input
A9: Revenue forecast basis | B9: Segment-driven base-case revenue growth; Integrated DCF is now bottom-up from segment operating income less a normalized corporate/unallocated cost bridge.
A10: EBIT margin normalization | B10: FY26A reported operating margin is 20.3%; FY27E onward consolidated EBIT is derived bottom-up from segment operating income less normalized unallocable/corporate costs. This produces a consolidated margin consistent with the 20%-22% company guidance range.
A11: Scenario design | B11: Bear/Base/Bull operating assumptions (revenue growth, EBIT margin, terminal inputs) flow directly into three separately computed scenario DCFs
A12: Cross-check design | B12: The single FCFF DCF is expressed through a top-down Legacy build and a bottom-up Integrated build. The Integrated build aggregates segment operating income and explicitly reconciles it to consolidated EBIT through normalized corporate/unallocated costs; the two builds are an internal build-integrity check, not independent valuations.
A13: Comps | B13: TCS, HCL Technologies, Wipro, Tech Mahindra, LTIMindtree, plus mid-cap context; independent market cross-check, not used to force the DCF
A14: Beta | B14: Peer-based unlevered beta re-levered to Infosys capital structure; 2-year weekly regression
... A18: Deliverables | B18: Deliverables: Excel model + written investment note + tear sheet. Beta data is refreshed through the week of 18 Aug 2026 (last observation 16 Aug 2026), the last trading week before the 22 Aug 2026 valuation date.

Sheet HistoricalFS
B2: ="Historical Financial Statement - "&'Data Sheet'!B1 -> Historical Financial Statement - INFOSYS LTD
B3: Years | C3: ='Data Sheet'!B16 -> 42825 | D3: ='Data Sheet'!C16 -> 43190 | E3: ='Data Sheet'!D16 -> 43555 | F3: ='Data Sheet'!E16 -> 43921 | G3: ='Data Sheet'!F16 -> 44286 | H3: ='Data Sheet'!G16 -> 44651 | I3: ='Data Sheet'!H16 -> 45016 | J3: ='Data Sheet'!I16 -> 45382 | ... L3: ='Data Sheet'!K16 -> 46112 | M3: LTM
A5: # | B5: Income Statement
B6: Sales | C6: =IFERROR('Data Sheet'!B17,0) -> 68484 | D6: =IFERROR('Data Sheet'!C17,0) -> 70522 | E6: =IFERROR('Data Sheet'!D17,0) -> 82675 | F6: =IFERROR('Data Sheet'!E17,0) -> 90791 | G6: =IFERROR('Data Sheet'!F17,0) -> 100472 | H6: =IFERROR('Data Sheet'!G17,0) -> 121641 | I6: =IFERROR('Data Sheet'!H17,0) -> 146767 | J6: =IFERROR('Data Sheet'!I17,0) -> 153670 | ... L6: =IFERROR('Data Sheet'!K17,0) -> 178650 | M6: =IFERROR(SUM('Data Sheet'!H42:K42),0) -> 184582
B7: Sales Growth | C7: - | D7: =D6/C6-1 -> 0.029758776 | E7: =E6/D6-1 -> 0.1723292 | F7: =F6/E6-1 -> 0.098167523 | G7: =G6/F6-1 -> 0.10662951 | H7: =H6/G6-1 -> 0.21069552 | I7: =I6/H6-1 -> 0.20655864 | J7: =J6/I6-1 -> 0.047033734 | K7: =K6/J6-1 -> 0.060649444 | ... M7: =M6/L6-1 -> 0.03320459
B9: COGS | C9: =IFERROR(SUM('Data Sheet'!B18,'Data Sheet'!B20:B22)-1*'Data Sheet'!B19,0) -> 44609 | D9: =IFERROR(SUM('Data Sheet'!C18,'Data Sheet'!C20:C22)-1*'Data Sheet'!C19,0) -> 46395 | E9: =IFERROR(SUM('Data Sheet'!D18,'Data Sheet'!D20:D22)-1*'Data Sheet'!D19,0) -> 55446 | F9: =IFERROR(SUM('Data Sheet'!E18,'Data Sheet'!E20:E22)-1*'Data Sheet'!E19,0) -> 62210 | G9: =IFERROR(SUM('Data Sheet'!F18,'Data Sheet'!F20:F22)-1*'Data Sheet'!F19,0) -> 68490 | H9: =IFERROR(SUM('Data Sheet'!G18,'Data Sheet'!G20:G22)-1*'Data Sheet'!G19,0) -> 84819 | I9: =IFERROR(SUM('Data Sheet'!H18,'Data Sheet'!H20:H22)-1*'Data Sheet'!H19,0) -> 104880 | J9: =IFERROR(SUM('Data Sheet'!I18,'Data Sheet'!I20:I22)-1*'Data Sheet'!I19,0) -> 110030 | ... L9: =IFERROR(SUM('Data Sheet'!K18,'Data Sheet'!K20:K22)-1*'Data Sheet'!K19,0) -> 128257 | M9: =IFERROR(SUM('Data Sheet'!H43:K43),0) -> 140837
B10: COGS % Sales | C10: =C9/C6 -> 0.65137842 | D10: =D9/D6 -> 0.65787981 | E10: =E9/E6 -> 0.67065014 | F10: =F9/F6 -> 0.68520007 | G10: =G9/G6 -> 0.68168246 | H10: =H9/H6 -> 0.69728957 | I10: =I9/I6 -> 0.71460206 | J10: =J9/J6 -> 0.71601484 | ... M10: =M9/M6 -> 0.76300506
B12: Gross Profit | C12: =C6-C9 -> 23875 | D12: =D6-D9 -> 24127 | E12: =E6-E9 -> 27229 | F12: =F6-F9 -> 28581 | G12: =G6-G9 -> 31982 | H12: =H6-H9 -> 36822 | I12: =I6-I9 -> 41887 | J12: =J6-J9 -> 43640 | ... M12: =M6-M9 -> 43745
B13: Gross Margins | C13: =C12/C6 -> 0.34862158 | D13: =D12/D6 -> 0.34212019 | E13: =E12/E6 -> 0.32934986 | F13: =F12/F6 -> 0.31479993 | G13: =G12/G6 -> 0.31831754 | H13: =H12/H6 -> 0.30271043 | I13: =I12/I6 -> 0.28539794 | J13: =J12/J6 -> 0.28398516 | ... M13: =M12/M6 -> 0.23699494
B15: Selling & General Expenses | C15: =IFERROR(SUM('Data Sheet'!B23:B24),0) -> 5271 | D15: =IFERROR(SUM('Data Sheet'!C23:C24),0) -> 5305 | E15: =IFERROR(SUM('Data Sheet'!D23:D24),0) -> 7059 | F15: =IFERROR(SUM('Data Sheet'!E23:E24),0) -> 6314 | G15: =IFERROR(SUM('Data Sheet'!F23:F24),0) -> 4093 | H15: =IFERROR(SUM('Data Sheet'!G23:G24),0) -> 5331 | I15: =IFERROR(SUM('Data Sheet'!H23:H24),0) -> 6757 | J15: =IFERROR(SUM('Data Sheet'!I23:I24),0) -> 7215 | ... L15: =IFERROR(SUM('Data Sheet'!K23:K24),0) -> 8113
B16: S&G Exp % Sales | C16: =C15/C6 -> 0.076966883 | D16: =D15/D6 -> 0.075224753 | E16: =E15/E6 -> 0.085382522 | F16: =F15/F6 -> 0.069544338 | G16: =G15/G6 -> 0.040737718 | H16: =H15/H6 -> 0.043825684 | I16: =I15/I6 -> 0.04603896 | J16: =J15/J6 -> 0.046951259 | ... L16: =L15/L6 -> 0.045412818
B18: EBITDA | C18: =C12-C15 -> 18604 | D18: =D12-D15 -> 18822 | E18: =E12-E15 -> 20170 | F18: =F12-F15 -> 22267 | G18: =G12-G15 -> 27889 | H18: =H12-H15 -> 31491 | I18: =I12-I15 -> 35130 | J18: =J12-J15 -> 36425 | ... L18: =L12-L15 -> 42280 | M18: =IFERROR(SUM('Data Sheet'!H51:K51),0) -> 46683
B19: EBITDA % Margins | C19: =C18/C6 -> 0.27165469 | D19: =D18/D6 -> 0.26689544 | E19: =E18/E6 -> 0.24396734 | F19: =F18/F6 -> 0.24525559 | G19: =G18/G6 -> 0.27757982 | H19: =H18/H6 -> 0.25888475 | I19: =I18/I6 -> 0.23935898 | J19: =J18/J6 -> 0.2370339 | ... M19: =M18/M6 -> 0.25291198
B21: Interest | C21: =IFERROR('Data Sheet'!B27,0) -> 0 | D21: =IFERROR('Data Sheet'!C27,0) -> 0 | E21: =IFERROR('Data Sheet'!D27,0) -> 0 | F21: =IFERROR('Data Sheet'!E27,0) -> 170 | G21: =IFERROR('Data Sheet'!F27,0) -> 195 | H21: =IFERROR('Data Sheet'!G27,0) -> 200 | I21: =IFERROR('Data Sheet'!H27,0) -> 284 | J21: =IFERROR('Data Sheet'!I27,0) -> 470 | ... L21: =IFERROR('Data Sheet'!K27,0) -> 416 | M21: =IFERROR(SUM('Data Sheet'!H46:K46),0) -> 430
B22: Interest % Sales | C22: =C21/C6 -> 0 | D22: =D21/D6 -> 0 | E22: =E21/E6 -> 0 | F22: =F21/F6 -> 0.0018724323 | G22: =G21/G6 -> 0.0019408392 | H22: =H21/H6 -> 0.0016441825 | I22: =I21/I6 -> 0.0019350399 | J22: =J21/J6 -> 0.003058502 | ... M22: =M21/M6 -> 0.0023295879
B24: Depreciation | C24: =IFERROR('Data Sheet'!B26,0) -> 1703 | D24: =IFERROR('Data Sheet'!C26,0) -> 1863 | E24: =IFERROR('Data Sheet'!D26,0) -> 2011 | F24: =IFERROR('Data Sheet'!E26,0) -> 2893 | G24: =IFERROR('Data Sheet'!F26,0) -> 3267 | H24: =IFERROR('Data Sheet'!G26,0) -> 3476 | I24: =IFERROR('Data Sheet'!H26,0) -> 4225 | J24: =IFERROR('Data Sheet'!I26,0) -> 4678 | ... L24: =IFERROR('Data Sheet'!K26,0) -> 4902 | M24: =IFERROR(SUM('Data Sheet'!H45:K45),0) -> 5007
B25: Depreciations % Sales | C25: =C24/C6 -> 0.024867122 | D25: =D24/D6 -> 0.026417288 | E25: =E24/E6 -> 0.024324161 | F25: =F24/F6 -> 0.031864392 | G25: =G24/G6 -> 0.032516522 | H25: =H24/H6 -> 0.028575891 | I25: =I24/I6 -> 0.028787125 | J25: =J24/J6 -> 0.030441856 | ... M25: =M24/M6 -> 0.027126155
B27: Earnings Before Tax | C27: =IFERROR(C18-SUM(C24,C21),0) -> 16901 | D27: =IFERROR(D18-SUM(D24,D21),0) -> 16959 | E27: =IFERROR(E18-SUM(E24,E21),0) -> 18159 | F27: =IFERROR(F18-SUM(F24,F21),0) -> 19204 | G27: =IFERROR(G18-SUM(G24,G21),0) -> 24427 | H27: =IFERROR(H18-SUM(H24,H21),0) -> 27815 | I27: =IFERROR(I18-SUM(I24,I21),0) -> 30621 | J27: =IFERROR(J18-SUM(J24,J21),0) -> 31277 | ... M27: =IFERROR(M18-SUM(M24,M21),0) -> 41246
B28: EBT % Sales | C28: =C27/C6 -> 0.24678757 | D28: =D27/D6 -> 0.24047815 | E28: =E27/E6 -> 0.21964318 | F28: =F27/F6 -> 0.21151876 | G28: =G27/G6 -> 0.24312246 | H28: =H27/H6 -> 0.22866468 | I28: =I27/I6 -> 0.20863682 | J28: =J27/J6 -> 0.20353355 | ... M28: =M27/M6 -> 0.22345624
B30: Tax | C30: =IFERROR('Data Sheet'!B29,0) -> 5598 | D30: =IFERROR('Data Sheet'!C29,0) -> 4241 | E30: =IFERROR('Data Sheet'!D29,0) -> 5631 | F30: =IFERROR('Data Sheet'!E29,0) -> 5368 | G30: =IFERROR('Data Sheet'!F29,0) -> 7205 | H30: =IFERROR('Data Sheet'!G29,0) -> 7964 | I30: =IFERROR('Data Sheet'!H29,0) -> 9214 | J30: =IFERROR('Data Sheet'!I29,0) -> 9740 | ... L30: =IFERROR('Data Sheet'!K29,0) -> 10521 | M30: =IFERROR(SUM('Data Sheet'!H48:K48),0) -> 10958
B31: Effective Tax Rate | C31: =C30/C27 -> 0.331223 | D31: =D30/D27 -> 0.25007371 | E31: =E30/E27 -> 0.31009417 | F31: =F30/F27 -> 0.2795251 | G31: =G30/G27 -> 0.29496049 | H31: =H30/H27 -> 0.28632033 | I31: =I30/I27 -> 0.30090461 | J31: =J30/J27 -> 0.31141094 | ... M31: =M30/M27 -> 0.26567425
B33: Net Profit | C33: =IFERROR(C27-C30,0) -> 11303 | D33: =IFERROR(D27-D30,0) -> 12718 | E33: =IFERROR(E27-E30,0) -> 12528 | F33: =IFERROR(F27-F30,0) -> 13836 | G33: =IFERROR(G27-G30,0) -> 17222 | H33: =IFERROR(H27-H30,0) -> 19851 | I33: =IFERROR(I27-I30,0) -> 21407 | J33: =IFERROR(J27-J30,0) -> 21537 | ... M33: =IFERROR(M27-M30,0) -> 30288
B34: Net Margins | C34: =C33/C6 -> 0.16504585 | D34: =D33/D6 -> 0.18034089 | E34: =E33/E6 -> 0.15153311 | F34: =F33/F6 -> 0.15239396 | G34: =G33/G6 -> 0.17141094 | H34: =H33/H6 -> 0.16319333 | I34: =I33/I6 -> 0.14585704 | J34: =J33/J6 -> 0.14015097 | ... M34: =M33/M6 -> 0.16408967
B36: No of Equity Shares | C36: =IFERROR('Data Sheet'!B93,0) -> 459.39 | D36: =IFERROR('Data Sheet'!C93,0) -> 436.82 | E36: =IFERROR('Data Sheet'!D93,0) -> 436.89 | F36: =IFERROR('Data Sheet'!E93,0) -> 425.9 | G36: =IFERROR('Data Sheet'!F93,0) -> 426.07 | H36: =IFERROR('Data Sheet'!G93,0) -> 420.67 | I36: =IFERROR('Data Sheet'!H93,0) -> 414.86 | J36: =IFERROR('Data Sheet'!I93,0) -> 415.09 | ... L36: =IFERROR('Data Sheet'!K93,0) -> 405.56 | M36: ='Data Sheet'!B6 -> 405.81
B38: EPS | C38: =IFERROR(C33/C36,0) -> 24.604367 | D38: =IFERROR(D33/D36,0) -> 29.114967 | E38: =IFERROR(E33/E36,0) -> 28.67541 | F38: =IFERROR(F33/F36,0) -> 32.486499 | G38: =IFERROR(G33/G36,0) -> 40.420588 | H38: =IFERROR(H33/H36,0) -> 47.189008 | I38: =IFERROR(I33/I36,0) -> 51.60054 | J38: =IFERROR(J33/J36,0) -> 51.885133 | ... M38: =IFERROR(M33/M36,0) -> 74.635913
B39: EPS Growth % | D39: =IFERROR((D38-C38)/ABS(C38),0) -> 0.18332521 | E39: =IFERROR(E38/D38-1,0) -> -0.015097286 | F39: =IFERROR(F38/E38-1,0) -> 0.13290442 | G39: =IFERROR(G38/F38-1,0) -> 0.24422727 | H39: =IFERROR(H38/G38-1,0) -> 0.16744981 | I39: =IFERROR(I38/H38-1,0) -> 0.093486431 | J39: =IFERROR(J38/I38-1,0) -> 0.0055153183 | K39: =IFERROR(K38/J38-1,0) -> 0.074273236 | L39: =IFERROR(L38/K38-1,0) -> 0.16967463 | M39: =IFERROR(M38/L38-1,0) -> 0.14478806
B41: Dividend Per Share | C41: =IFERROR('Data Sheet'!B31/HistoricalFS!C36,0) -> 12.824833 | D41: =IFERROR('Data Sheet'!C31/HistoricalFS!D36,0) -> 21.669337 | E41: =IFERROR('Data Sheet'!D31/HistoricalFS!E36,0) -> 21.109433 | F41: =IFERROR('Data Sheet'!E31/HistoricalFS!F36,0) -> 17.438366 | G41: =IFERROR('Data Sheet'!F31/HistoricalFS!G36,0) -> 26.91952 | H41: =IFERROR('Data Sheet'!G31/HistoricalFS!H36,0) -> 30.92115 | I41: =IFERROR('Data Sheet'!H31/HistoricalFS!I36,0) -> 33.913127 | J41: =IFERROR('Data Sheet'!I31/HistoricalFS!J36,0) -> 45.901371 | ... M41: =IFERROR('Data Sheet'!L31/HistoricalFS!M36,0) -> 0
B42: Divident payout ratio | C42: =IFERROR(C41/C38,0) -> 0.52124215 | D42: =IFERROR(D41/D38,0) -> 0.74426797 | E42: =IFERROR(E41/E38,0) -> 0.73615102 | F42: =IFERROR(F41/F38,0) -> 0.53678809 | G42: =IFERROR(G41/G38,0) -> 0.66598537 | H42: =IFERROR(H41/H38,0) -> 0.6552617 | I42: =IFERROR(I41/I38,0) -> 0.65722427 | J42: =IFERROR(J41/J38,0) -> 0.88467289 | ... M42: =IFERROR(M41/M38,0) -> 0
B44: Retention Ratio | C44: =IFERROR(IF(C38>C41,1-C42,0),0) -> 0.47875785 | D44: =IFERROR(IF(D38>D41,1-D42,0),0) -> 0.25573203 | E44: =IFERROR(IF(E38>E41,1-E42,0),0) -> 0.26384898 | F44: =IFERROR(IF(F38>F41,1-F42,0),0) -> 0.46321191 | G44: =IFERROR(IF(G38>G41,1-G42,0),0) -> 0.33401463 | H44: =IFERROR(IF(H38>H41,1-H42,0),0) -> 0.3447383 | I44: =IFERROR(IF(I38>I41,1-I42,0),0) -> 0.34277573 | J44: =IFERROR(IF(J38>J41,1-J42,0),0) -> 0.11532711 | ... M44: =IFERROR(IF(M38>M41,1-M42,0),0) -> 1
A46: # | B46: Balance Sheet
B47: Equity Share Capital | C47: =IFERROR('Data Sheet'!B57,0) -> 1144 | D47: =IFERROR('Data Sheet'!C57,0) -> 1088 | E47: =IFERROR('Data Sheet'!D57,0) -> 2170 | F47: =IFERROR('Data Sheet'!E57,0) -> 2122 | G47: =IFERROR('Data Sheet'!F57,0) -> 2124 | H47: =IFERROR('Data Sheet'!G57,0) -> 2098 | I47: =IFERROR('Data Sheet'!H57,0) -> 2069 | J47: =IFERROR('Data Sheet'!I57,0) -> 2071 | ... L47: =IFERROR('Data Sheet'!K57,0) -> 2024
B48: Reserves | C48: =IFERROR('Data Sheet'!B58,0) -> 67838 | D48: =IFERROR('Data Sheet'!C58,0) -> 63835 | E48: =IFERROR('Data Sheet'!D58,0) -> 62778 | F48: =IFERROR('Data Sheet'!E58,0) -> 63328 | G48: =IFERROR('Data Sheet'!F58,0) -> 74227 | H48: =IFERROR('Data Sheet'!G58,0) -> 73252 | I48: =IFERROR('Data Sheet'!H58,0) -> 73338 | J48: =IFERROR('Data Sheet'!I58,0) -> 86045 | ... L48: =IFERROR('Data Sheet'!K58,0) -> 90828
B49: Borrowings | C49: =IFERROR('Data Sheet'!B59,0) -> 0 | D49: =IFERROR('Data Sheet'!C59,0) -> 0 | E49: =IFERROR('Data Sheet'!D59,0) -> 0 | F49: =IFERROR('Data Sheet'!E59,0) -> 4633 | G49: =IFERROR('Data Sheet'!F59,0) -> 5325 | H49: =IFERROR('Data Sheet'!G59,0) -> 5474 | I49: =IFERROR('Data Sheet'!H59,0) -> 8299 | J49: =IFERROR('Data Sheet'!I59,0) -> 8359 | ... L49: =IFERROR('Data Sheet'!K59,0) -> 9176
B50: Other Liabilities | C50: =IFERROR('Data Sheet'!B60,0) -> 14166 | D50: =IFERROR('Data Sheet'!C60,0) -> 14426 | E50: =IFERROR('Data Sheet'!D60,0) -> 19118 | F50: =IFERROR('Data Sheet'!E60,0) -> 21717 | G50: =IFERROR('Data Sheet'!F60,0) -> 25835 | H50: =IFERROR('Data Sheet'!G60,0) -> 35905 | I50: =IFERROR('Data Sheet'!H60,0) -> 40890 | J50: =IFERROR('Data Sheet'!I60,0) -> 39545 | ... L50: =IFERROR('Data Sheet'!K60,0) -> 52260
B51: Total Liabilities | C51: =IFERROR('Data Sheet'!B61,0) -> 83148 | D51: =IFERROR('Data Sheet'!C61,0) -> 79349 | E51: =IFERROR('Data Sheet'!D61,0) -> 84066 | F51: =IFERROR('Data Sheet'!E61,0) -> 91800 | G51: =IFERROR('Data Sheet'!F61,0) -> 107511 | H51: =IFERROR('Data Sheet'!G61,0) -> 116729 | I51: =IFERROR('Data Sheet'!H61,0) -> 124596 | J51: =IFERROR('Data Sheet'!I61,0) -> 136020 | ... L51: =IFERROR('Data Sheet'!K61,0) -> 154288
B53: Fixed Assets Net Block | C53: =IFERROR('Data Sheet'!B62,0) -> 14179 | D53: =IFERROR('Data Sheet'!C62,0) -> 12574 | E53: =IFERROR('Data Sheet'!D62,0) -> 15710 | F53: =IFERROR('Data Sheet'!E62,0) -> 23789 | G53: =IFERROR('Data Sheet'!F62,0) -> 25505 | H53: =IFERROR('Data Sheet'!G62,0) -> 25800 | I53: =IFERROR('Data Sheet'!H62,0) -> 29225 | J53: =IFERROR('Data Sheet'!I62,0) -> 27622 | ... L53: =IFERROR('Data Sheet'!K62,0) -> 33770
B54: Capital Work in Progress | C54: =IFERROR('Data Sheet'!B63,0) -> 1365 | D54: =IFERROR('Data Sheet'!C63,0) -> 1606 | E54: =IFERROR('Data Sheet'!D63,0) -> 1388 | F54: =IFERROR('Data Sheet'!E63,0) -> 954 | G54: =IFERROR('Data Sheet'!F63,0) -> 922 | H54: =IFERROR('Data Sheet'!G63,0) -> 416 | I54: =IFERROR('Data Sheet'!H63,0) -> 288 | J54: =IFERROR('Data Sheet'!I63,0) -> 293 | ... L54: =IFERROR('Data Sheet'!K63,0) -> 526
B55: Investments | C55: =IFERROR('Data Sheet'!B64,0) -> 16423 | D55: =IFERROR('Data Sheet'!C64,0) -> 12163 | E55: =IFERROR('Data Sheet'!D64,0) -> 11261 | F55: =IFERROR('Data Sheet'!E64,0) -> 8792 | G55: =IFERROR('Data Sheet'!F64,0) -> 14205 | H55: =IFERROR('Data Sheet'!G64,0) -> 20324 | I55: =IFERROR('Data Sheet'!H64,0) -> 19478 | J55: =IFERROR('Data Sheet'!I64,0) -> 24623 | ... L55: =IFERROR('Data Sheet'!K64,0) -> 21880
B56: Other Assets | C56: =IFERROR('Data Sheet'!B65-SUM('Data Sheet'!B67:B69),0) -> 16234 | D56: =IFERROR('Data Sheet'!C65-SUM('Data Sheet'!C67:C69),0) -> 20046 | E56: =IFERROR('Data Sheet'!D65-SUM('Data Sheet'!D67:D69),0) -> 21312 | F56: =IFERROR('Data Sheet'!E65-SUM('Data Sheet'!E67:E69),0) -> 21129 | G56: =IFERROR('Data Sheet'!F65-SUM('Data Sheet'!F67:F69),0) -> 22871 | H56: =IFERROR('Data Sheet'!G65-SUM('Data Sheet'!G67:G69),0) -> 30019 | I56: =IFERROR('Data Sheet'!H65-SUM('Data Sheet'!H67:H69),0) -> 38008 | J56: =IFERROR('Data Sheet'!I65-SUM('Data Sheet'!I67:I69),0) -> 38503 | ... L56: =IFERROR('Data Sheet'!K65-SUM('Data Sheet'!K67:K69),0) -> 40677
B57: Total Non Current Assets | C57: =SUM(C53:C56) -> 48201 | D57: =SUM(D53:D56) -> 46389 | E57: =SUM(E53:E56) -> 49671 | F57: =SUM(F53:F56) -> 54664 | G57: =SUM(G53:G56) -> 63503 | H57: =SUM(H53:H56) -> 76559 | I57: =SUM(I53:I56) -> 86999 | J57: =SUM(J53:J56) -> 91041 | ... L57: =SUM(L53:L56) -> 96853
...

Sheet Profit & Loss
A1: ='Data Sheet'!B1 -> INFOSYS LTD | H1: UPDATE | M1: SCREENER.IN
A3: Narration | B3: ='Data Sheet'!B16 -> 42825 | C3: ='Data Sheet'!C16 -> 43190 | D3: ='Data Sheet'!D16 -> 43555 | E3: ='Data Sheet'!E16 -> 43921 | F3: ='Data Sheet'!F16 -> 44286 | G3: ='Data Sheet'!G16 -> 44651 | H3: ='Data Sheet'!H16 -> 45016 | I3: ='Data Sheet'!I16 -> 45382 | ... K3: ='Data Sheet'!K16 -> 46112 | L3: Trailing | M3: Best Case | N3: Worst Case
A4: Sales | B4: ='Data Sheet'!B17 -> 68484 | C4: ='Data Sheet'!C17 -> 70522 | D4: ='Data Sheet'!D17 -> 82675 | E4: ='Data Sheet'!E17 -> 90791 | F4: ='Data Sheet'!F17 -> 100472 | G4: ='Data Sheet'!G17 -> 121641 | H4: ='Data Sheet'!H17 -> 146767 | I4: ='Data Sheet'!I17 -> 153670 | ... K4: ='Data Sheet'!K17 -> 178650 | L4: =SUM(Quarters!H4:K4) -> 184582 | M4: =$K4+M23*K4 -> 195814.61 | N4: =$K4+N23*L4 -> 191150.27
A5: Expenses | B5: =SUM('Data Sheet'!B18,'Data Sheet'!B20:B24, -1*'Data Sheet'!B19) -> 49880 | C5: =SUM('Data Sheet'!C18,'Data Sheet'!C20:C24, -1*'Data Sheet'!C19) -> 51700 | D5: =SUM('Data Sheet'!D18,'Data Sheet'!D20:D24, -1*'Data Sheet'!D19) -> 62505 | E5: =SUM('Data Sheet'!E18,'Data Sheet'!E20:E24, -1*'Data Sheet'!E19) -> 68524 | F5: =SUM('Data Sheet'!F18,'Data Sheet'!F20:F24, -1*'Data Sheet'!F19) -> 72583 | G5: =SUM('Data Sheet'!G18,'Data Sheet'!G20:G24, -1*'Data Sheet'!G19) -> 90150 | H5: =SUM('Data Sheet'!H18,'Data Sheet'!H20:H24, -1*'Data Sheet'!H19) -> 111637 | I5: =SUM('Data Sheet'!I18,'Data Sheet'!I20:I24, -1*'Data Sheet'!I19) -> 117245 | ... K5: =SUM('Data Sheet'!K18,'Data Sheet'!K20:K24, -1*'Data Sheet'!K19) -> 136370 | L5: =SUM(Quarters!H5:K5) -> 140837 | M5: =M4-M6 -> 149188.11 | N5: =N4-N6 -> 145848.62
A6: Operating Profit | B6: =B4-B5 -> 18604 | C6: =C4-C5 -> 18822 | D6: =D4-D5 -> 20170 | E6: =E4-E5 -> 22267 | F6: =F4-F5 -> 27889 | G6: =G4-G5 -> 31491 | H6: =H4-H5 -> 35130 | I6: =I4-I5 -> 36425 | ... K6: =K4-K5 -> 42280 | L6: =SUM(Quarters!H6:K6) -> 43745 | M6: =M4*M24 -> 46626.497 | N6: =N4*N24 -> 45301.646
A7: Other Income | B7: ='Data Sheet'!B25 -> 3050 | C7: ='Data Sheet'!C25 -> 3311 | D7: ='Data Sheet'!D25 -> 2882 | E7: ='Data Sheet'!E25 -> 2803 | F7: ='Data Sheet'!F25 -> 2201 | G7: ='Data Sheet'!G25 -> 2295 | H7: ='Data Sheet'!H25 -> 2701 | I7: ='Data Sheet'!I25 -> 4711 | ... K7: ='Data Sheet'!K25 -> 3033 | L7: =SUM(Quarters!H7:K7) -> 2975 | M7: 0 | N7: 0
A8: Depreciation | B8: ='Data Sheet'!B26 -> 1703 | C8: ='Data Sheet'!C26 -> 1863 | D8: ='Data Sheet'!D26 -> 2011 | E8: ='Data Sheet'!E26 -> 2893 | F8: ='Data Sheet'!F26 -> 3267 | G8: ='Data Sheet'!G26 -> 3476 | H8: ='Data Sheet'!H26 -> 4225 | I8: ='Data Sheet'!I26 -> 4678 | ... K8: ='Data Sheet'!K26 -> 4902 | L8: =SUM(Quarters!H8:K8) -> 5007 | M8: =+$L8 -> 5007 | N8: =+$L8 -> 5007
A9: Interest | B9: ='Data Sheet'!B27 -> 0 | C9: ='Data Sheet'!C27 -> 0 | D9: ='Data Sheet'!D27 -> 0 | E9: ='Data Sheet'!E27 -> 170 | F9: ='Data Sheet'!F27 -> 195 | G9: ='Data Sheet'!G27 -> 200 | H9: ='Data Sheet'!H27 -> 284 | I9: ='Data Sheet'!I27 -> 470 | ... K9: ='Data Sheet'!K27 -> 416 | L9: =SUM(Quarters!H9:K9) -> 430 | M9: =+$L9 -> 430 | N9: =+$L9 -> 430
A10: Profit before tax | B10: ='Data Sheet'!B28 -> 19951 | C10: ='Data Sheet'!C28 -> 20270 | D10: ='Data Sheet'!D28 -> 21041 | E10: ='Data Sheet'!E28 -> 22007 | F10: ='Data Sheet'!F28 -> 26628 | G10: ='Data Sheet'!G28 -> 30110 | H10: ='Data Sheet'!H28 -> 33322 | I10: ='Data Sheet'!I28 -> 35988 | ... K10: ='Data Sheet'!K28 -> 39995 | L10: =SUM(Quarters!H10:K10) -> 41283 | M10: =M6+M7-SUM(M8:M9) -> 41189.497 | N10: =N6+N7-SUM(N8:N9) -> 39864.646
A11: Tax | B11: ='Data Sheet'!B29 -> 5598 | C11: ='Data Sheet'!C29 -> 4241 | D11: ='Data Sheet'!D29 -> 5631 | E11: ='Data Sheet'!E29 -> 5368 | F11: ='Data Sheet'!F29 -> 7205 | G11: ='Data Sheet'!G29 -> 7964 | H11: ='Data Sheet'!H29 -> 9214 | I11: ='Data Sheet'!I29 -> 9740 | ... K11: ='Data Sheet'!K29 -> 10521 | L11: =SUM(Quarters!H11:K11) -> 10958 | M11: =IF($L10>0,$L11/$L10,0) -> 0.26543614 | N11: =IF($L10>0,$L11/$L10,0) -> 0.26543614
A12: Net profit | B12: ='Data Sheet'!B30 -> 14353 | C12: ='Data Sheet'!C30 -> 16029 | D12: ='Data Sheet'!D30 -> 15404 | E12: ='Data Sheet'!E30 -> 16594 | F12: ='Data Sheet'!F30 -> 19351 | G12: ='Data Sheet'!G30 -> 22110 | H12: ='Data Sheet'!H30 -> 24095 | I12: ='Data Sheet'!I30 -> 26233 | ... K12: ='Data Sheet'!K30 -> 29440 | L12: =SUM(Quarters!H12:K12) -> 30288 | M12: =M10-M11*M10 -> 30256.316 | N12: =N10-N11*N10 -> 29283.128
A13: EPS | B13: =IF('Data Sheet'!B93>0,B12/'Data Sheet'!B93,0) -> 31.243606 | C13: =IF('Data Sheet'!C93>0,C12/'Data Sheet'!C93,0) -> 36.694748 | D13: =IF('Data Sheet'!D93>0,D12/'Data Sheet'!D93,0) -> 35.258303 | E13: =IF('Data Sheet'!E93>0,E12/'Data Sheet'!E93,0) -> 38.962198 | F13: =IF('Data Sheet'!F93>0,F12/'Data Sheet'!F93,0) -> 45.41742 | G13: =IF('Data Sheet'!G93>0,G12/'Data Sheet'!G93,0) -> 52.559013 | H13: =IF('Data Sheet'!H93>0,H12/'Data Sheet'!H93,0) -> 58.079834 | I13: =IF('Data Sheet'!I93>0,I12/'Data Sheet'!I93,0) -> 63.198343 | ... K13: =IF('Data Sheet'!K93>0,K12/'Data Sheet'!K93,0) -> 72.590985 | L13: =IF('Data Sheet'!$B6>0,'Profit & Loss'!L12/'Data Sheet'!$B6,0) -> 74.635913 | M13: =IF('Data Sheet'!$B6>0,'Profit & Loss'!M12/'Data Sheet'!$B6,0) -> 74.557838 | N13: =IF('Data Sheet'!$B6>0,'Profit & Loss'!N12/'Data Sheet'!$B6,0) -> 72.159701
A14: Price to earning | B14: =IF(B15>0,B15/B13,"") -> 16.359507 | C14: =IF(C15>0,C15/C13,"") -> 15.421825 | D14: =IF(D15>0,D15/D13,"") -> 21.097158 | E14: =IF(E15>0,E15/E13,"") -> 16.464677 | F14: =IF(F15>0,F15/F13,"") -> 30.121702 | G14: =IF(G15>0,G15/G13,"") -> 36.280171 | H14: =IF(H15>0,H15/H13,"") -> 24.585986 | I14: =IF(I15>0,I15/I13,"") -> 23.703944 | ... K14: =IF(K15>0,K15/K13,"") -> 17.228035 | L14: =IF(L13>0,L15/L13,0) -> 15.019579 | M14: =M25 -> 20.092951 | N14: =N25 -> 15.019579
A15: Price | B15: ='Data Sheet'!B90 -> 511.13 | C15: ='Data Sheet'!C90 -> 565.9 | D15: ='Data Sheet'!D90 -> 743.85 | E15: ='Data Sheet'!E90 -> 641.5 | F15: ='Data Sheet'!F90 -> 1368.05 | G15: ='Data Sheet'!G90 -> 1906.85 | H15: ='Data Sheet'!H90 -> 1427.95 | I15: ='Data Sheet'!I90 -> 1498.05 | ... K15: ='Data Sheet'!K90 -> 1250.6 | L15: ='Data Sheet'!B8 -> 1121 | M15: =M13*M14 -> 1498.087 | N15: =N13*N14 -> 1083.8083
A17: RATIOS:
A18: Dividend Payout | B18: =IF('Data Sheet'!B30>0, 'Data Sheet'!B31/'Data Sheet'!B30, 0) -> 0.41047865 | C18: =IF('Data Sheet'!C30>0, 'Data Sheet'!C31/'Data Sheet'!C30, 0) -> 0.59052966 | D18: =IF('Data Sheet'!D30>0, 'Data Sheet'!D31/'Data Sheet'!D30, 0) -> 0.59870813 | E18: =IF('Data Sheet'!E30>0, 'Data Sheet'!E31/'Data Sheet'!E30, 0) -> 0.44757141 | F18: =IF('Data Sheet'!F30>0, 'Data Sheet'!F31/'Data Sheet'!F30, 0) -> 0.59271355 | G18: =IF('Data Sheet'!G30>0, 'Data Sheet'!G31/'Data Sheet'!G30, 0) -> 0.58831298 | H18: =IF('Data Sheet'!H30>0, 'Data Sheet'!H31/'Data Sheet'!H30, 0) -> 0.58390537 | I18: =IF('Data Sheet'!I30>0, 'Data Sheet'!I31/'Data Sheet'!I30, 0) -> 0.72630656 | ... K18: =IF('Data Sheet'!K30>0, 'Data Sheet'!K31/'Data Sheet'!K30, 0) -> 0.66
A19: OPM | B19: =IF(B6>0,B6/B4,0) -> 0.27165469 | C19: =IF(C6>0,C6/C4,0) -> 0.26689544 | D19: =IF(D6>0,D6/D4,0) -> 0.24396734 | E19: =IF(E6>0,E6/E4,0) -> 0.24525559 | F19: =IF(F6>0,F6/F4,0) -> 0.27757982 | G19: =IF(G6>0,G6/G4,0) -> 0.25888475 | H19: =IF(H6>0,H6/H4,0) -> 0.23935898 | I19: =IF(I6>0,I6/I4,0) -> 0.2370339 | ... L19: =IF(L6>0,L6/L4,0) -> 0.23699494
G22: TRENDS: | H22: 10 YEARS | I22: 7 YEARS | J22: 5 YEARS | K22: 3 YEARS | L22: RECENT | M22: BEST | N22: WORST
G23: Sales Growth | H23: =IF(B4=0,"",POWER($K4/B4,1/9)-1) -> 0.11241852 | I23: =IF(D4=0,"",POWER($K4/D4,1/7)-1) -> 0.11635961 | J23: =IF(F4=0,"",POWER($K4/F4,1/5)-1) -> 0.12199674 | K23: =IF(H4=0,"",POWER($K4/H4, 1/3)-1) -> 0.067722024 | L23: =IF(ISERROR(MAX(IF(J4=0,"",(K4-J4)/J4),IF(K4=0,"",(L4-K4)/K4))),"",MAX(IF(J4=0,"",(K4-J4)/J4),IF(K4=0,"",(L4-K4)/K4))) -> 0.096079514 | M23: =MAX(K23:L23) -> 0.096079514 | N23: =MIN(H23:L23) -> 0.067722024
G24: OPM | H24: =IF(SUM(B4:$K$4)=0,"",SUMPRODUCT(B19:$K$19,B4:$K$4)/SUM(B4:$K$4)) -> 0.24842648 | I24: =IF(SUM(E4:$K$4)=0,"",SUMPRODUCT(E19:$K$19,E4:$K$4)/SUM(E4:$K$4)) -> 0.2457829 | J24: =IF(SUM(G4:$K$4)=0,"",SUMPRODUCT(G19:$K$19,G4:$K$4)/SUM(G4:$K$4)) -> 0.2416625 | K24: =IF(SUM(I4:$K$4)=0, "", SUMPRODUCT(I19:$K$19,I4:$K$4)/SUM(I4:$K$4)) -> 0.23811552 | L24: =L19 -> 0.23699494 | M24: =MAX(K24:L24) -> 0.23811552 | N24: =MIN(H24:L24) -> 0.23699494
G25: Price to Earning | H25: =IF(ISERROR(AVERAGEIF(B14:$L14,">0")),"",AVERAGEIF(B14:$L14,">0")) -> 21.882076 | I25: =IF(ISERROR(AVERAGEIF(E14:$L14,">0")),"",AVERAGEIF(E14:$L14,">0")) -> 23.478043 | J25: =IF(ISERROR(AVERAGEIF(G14:$L14,">0")),"",AVERAGEIF(G14:$L14,">0")) -> 23.53966 | K25: =IF(ISERROR(AVERAGEIF(I14:$L14,">0")),"",AVERAGEIF(I14:$L14,">0")) -> 20.092951 | L25: =L14 -> 15.019579 | M25: =MAX(K25:L25) -> 20.092951 | N25: =MIN(H25:L25) -> 15.019579

Sheet Balance Sheet
A1: ='Profit & Loss'!A1 -> INFOSYS LTD | E1: UPDATE | J1: SCREENER.IN
A3: Narration | B3: ='Data Sheet'!B56 -> 42825 | C3: ='Data Sheet'!C56 -> 43190 | D3: ='Data Sheet'!D56 -> 43555 | E3: ='Data Sheet'!E56 -> 43921 | F3: ='Data Sheet'!F56 -> 44286 | G3: ='Data Sheet'!G56 -> 44651 | H3: ='Data Sheet'!H56 -> 45016 | I3: ='Data Sheet'!I56 -> 45382 | ... K3: ='Data Sheet'!K56 -> 46112
A4: Equity Share Capital | B4: ='Data Sheet'!B57 -> 1144 | C4: ='Data Sheet'!C57 -> 1088 | D4: ='Data Sheet'!D57 -> 2170 | E4: ='Data Sheet'!E57 -> 2122 | F4: ='Data Sheet'!F57 -> 2124 | G4: ='Data Sheet'!G57 -> 2098 | H4: ='Data Sheet'!H57 -> 2069 | I4: ='Data Sheet'!I57 -> 2071 | ... K4: ='Data Sheet'!K57 -> 2024
A5: Reserves | B5: ='Data Sheet'!B58 -> 67838 | C5: ='Data Sheet'!C58 -> 63835 | D5: ='Data Sheet'!D58 -> 62778 | E5: ='Data Sheet'!E58 -> 63328 | F5: ='Data Sheet'!F58 -> 74227 | G5: ='Data Sheet'!G58 -> 73252 | H5: ='Data Sheet'!H58 -> 73338 | I5: ='Data Sheet'!I58 -> 86045 | ... K5: ='Data Sheet'!K58 -> 90828
A6: Borrowings | B6: ='Data Sheet'!B59 -> 0 | C6: ='Data Sheet'!C59 -> 0 | D6: ='Data Sheet'!D59 -> 0 | E6: ='Data Sheet'!E59 -> 4633 | F6: ='Data Sheet'!F59 -> 5325 | G6: ='Data Sheet'!G59 -> 5474 | H6: ='Data Sheet'!H59 -> 8299 | I6: ='Data Sheet'!I59 -> 8359 | ... K6: ='Data Sheet'!K59 -> 9176
A7: Other Liabilities | B7: ='Data Sheet'!B60 -> 14166 | C7: ='Data Sheet'!C60 -> 14426 | D7: ='Data Sheet'!D60 -> 19118 | E7: ='Data Sheet'!E60 -> 21717 | F7: ='Data Sheet'!F60 -> 25835 | G7: ='Data Sheet'!G60 -> 35905 | H7: ='Data Sheet'!H60 -> 40890 | I7: ='Data Sheet'!I60 -> 39545 | ... K7: ='Data Sheet'!K60 -> 52260
A8: Total | B8: ='Data Sheet'!B61 -> 83148 | C8: ='Data Sheet'!C61 -> 79349 | D8: ='Data Sheet'!D61 -> 84066 | E8: ='Data Sheet'!E61 -> 91800 | F8: ='Data Sheet'!F61 -> 107511 | G8: ='Data Sheet'!G61 -> 116729 | H8: ='Data Sheet'!H61 -> 124596 | I8: ='Data Sheet'!I61 -> 136020 | ... K8: ='Data Sheet'!K61 -> 154288
A10: Net Block | B10: ='Data Sheet'!B62 -> 14179 | C10: ='Data Sheet'!C62 -> 12574 | D10: ='Data Sheet'!D62 -> 15710 | E10: ='Data Sheet'!E62 -> 23789 | F10: ='Data Sheet'!F62 -> 25505 | G10: ='Data Sheet'!G62 -> 25800 | H10: ='Data Sheet'!H62 -> 29225 | I10: ='Data Sheet'!I62 -> 27622 | ... K10: ='Data Sheet'!K62 -> 33770
A11: Capital Work in Progress | B11: ='Data Sheet'!B63 -> 1365 | C11: ='Data Sheet'!C63 -> 1606 | D11: ='Data Sheet'!D63 -> 1388 | E11: ='Data Sheet'!E63 -> 954 | F11: ='Data Sheet'!F63 -> 922 | G11: ='Data Sheet'!G63 -> 416 | H11: ='Data Sheet'!H63 -> 288 | I11: ='Data Sheet'!I63 -> 293 | ... K11: ='Data Sheet'!K63 -> 526
A12: Investments | B12: ='Data Sheet'!B64 -> 16423 | C12: ='Data Sheet'!C64 -> 12163 | D12: ='Data Sheet'!D64 -> 11261 | E12: ='Data Sheet'!E64 -> 8792 | F12: ='Data Sheet'!F64 -> 14205 | G12: ='Data Sheet'!G64 -> 20324 | H12: ='Data Sheet'!H64 -> 19478 | I12: ='Data Sheet'!I64 -> 24623 | ... K12: ='Data Sheet'!K64 -> 21880
A13: Other Assets | B13: ='Data Sheet'!B65 -> 51181 | C13: ='Data Sheet'!C65 -> 53006 | D13: ='Data Sheet'!D65 -> 55707 | E13: ='Data Sheet'!E65 -> 58265 | F13: ='Data Sheet'!F65 -> 66879 | G13: ='Data Sheet'!G65 -> 70189 | H13: ='Data Sheet'!H65 -> 75605 | I13: ='Data Sheet'!I65 -> 83482 | ... K13: ='Data Sheet'!K65 -> 98112
A14: Total | B14: ='Data Sheet'!B66 -> 83148 | C14: ='Data Sheet'!C66 -> 79349 | D14: ='Data Sheet'!D66 -> 84066 | E14: ='Data Sheet'!E66 -> 91800 | F14: ='Data Sheet'!F66 -> 107511 | G14: ='Data Sheet'!G66 -> 116729 | H14: ='Data Sheet'!H66 -> 124596 | I14: ='Data Sheet'!I66 -> 136020 | ... K14: ='Data Sheet'!K66 -> 154288
A16: Working Capital | B16: =B13-B7 -> 37015 | C16: =C13-C7 -> 38580 | D16: =D13-D7 -> 36589 | E16: =E13-E7 -> 36548 | F16: =F13-F7 -> 41044 | G16: =G13-G7 -> 34284 | H16: =H13-H7 -> 34715 | I16: =I13-I7 -> 43937 | ... K16: =K13-K7 -> 45852
A17: Debtors | B17: ='Data Sheet'!B67 -> 12322 | C17: ='Data Sheet'!C67 -> 13142 | D17: ='Data Sheet'!D67 -> 14827 | E17: ='Data Sheet'!E67 -> 18487 | F17: ='Data Sheet'!F67 -> 19294 | G17: ='Data Sheet'!G67 -> 22698 | H17: ='Data Sheet'!H67 -> 25424 | I17: ='Data Sheet'!I67 -> 30193 | ... K17: ='Data Sheet'!K67 -> 35234
A18: Inventory | B18: ='Data Sheet'!B68 -> 0 | C18: ='Data Sheet'!C68 -> 0 | D18: ='Data Sheet'!D68 -> 0 | E18: ='Data Sheet'!E68 -> 0 | F18: ='Data Sheet'!F68 -> 0 | G18: ='Data Sheet'!G68 -> 0 | H18: ='Data Sheet'!H68 -> 0 | I18: ='Data Sheet'!I68 -> 0 | ... K18: ='Data Sheet'!K68 -> 0
A20: Debtor Days | B20: =IF('Profit & Loss'!B4>0,'Balance Sheet'!B17/('Profit & Loss'!B4/365),0) -> 65.672712 | C20: =IF('Profit & Loss'!C4>0,'Balance Sheet'!C17/('Profit & Loss'!C4/365),0) -> 68.018916 | D20: =IF('Profit & Loss'!D4>0,'Balance Sheet'!D17/('Profit & Loss'!D4/365),0) -> 65.459389 | E20: =IF('Profit & Loss'!E4>0,'Balance Sheet'!E17/('Profit & Loss'!E4/365),0) -> 74.321849 | F20: =IF('Profit & Loss'!F4>0,'Balance Sheet'!F17/('Profit & Loss'!F4/365),0) -> 70.092265 | G20: =IF('Profit & Loss'!G4>0,'Balance Sheet'!G17/('Profit & Loss'!G4/365),0) -> 68.108368 | H20: =IF('Profit & Loss'!H4>0,'Balance Sheet'!H17/('Profit & Loss'!H4/365),0) -> 63.227837 | I20: =IF('Profit & Loss'!I4>0,'Balance Sheet'!I17/('Profit & Loss'!I4/365),0) -> 71.715006 | ... K20: =IF('Profit & Loss'!K4>0,'Balance Sheet'!K17/('Profit & Loss'!K4/365),0) -> 71.986622
A21: Inventory Turnover | B21: =IF('Balance Sheet'!B18>0,'Profit & Loss'!B4/'Balance Sheet'!B18,0) -> 0 | C21: =IF('Balance Sheet'!C18>0,'Profit & Loss'!C4/'Balance Sheet'!C18,0) -> 0 | D21: =IF('Balance Sheet'!D18>0,'Profit & Loss'!D4/'Balance Sheet'!D18,0) -> 0 | E21: =IF('Balance Sheet'!E18>0,'Profit & Loss'!E4/'Balance Sheet'!E18,0) -> 0 | F21: =IF('Balance Sheet'!F18>0,'Profit & Loss'!F4/'Balance Sheet'!F18,0) -> 0 | G21: =IF('Balance Sheet'!G18>0,'Profit & Loss'!G4/'Balance Sheet'!G18,0) -> 0 | H21: =IF('Balance Sheet'!H18>0,'Profit & Loss'!H4/'Balance Sheet'!H18,0) -> 0 | I21: =IF('Balance Sheet'!I18>0,'Profit & Loss'!I4/'Balance Sheet'!I18,0) -> 0 | ... K21: =IF('Balance Sheet'!K18>0,'Profit & Loss'!K4/'Balance Sheet'!K18,0) -> 0
A23: Return on Equity | B23: =IF(SUM('Balance Sheet'!B4:B5)>0,'Profit & Loss'!B12/SUM('Balance Sheet'!B4:B5),"") -> 0.20806877 | C23: =IF(SUM('Balance Sheet'!C4:C5)>0,'Profit & Loss'!C12/SUM('Balance Sheet'!C4:C5),"") -> 0.24689247 | D23: =IF(SUM('Balance Sheet'!D4:D5)>0,'Profit & Loss'!D12/SUM('Balance Sheet'!D4:D5),"") -> 0.23717435 | E23: =IF(SUM('Balance Sheet'!E4:E5)>0,'Profit & Loss'!E12/SUM('Balance Sheet'!E4:E5),"") -> 0.25353705 | F23: =IF(SUM('Balance Sheet'!F4:F5)>0,'Profit & Loss'!F12/SUM('Balance Sheet'!F4:F5),"") -> 0.25344789 | G23: =IF(SUM('Balance Sheet'!G4:G5)>0,'Profit & Loss'!G12/SUM('Balance Sheet'!G4:G5),"") -> 0.29343066 | H23: =IF(SUM('Balance Sheet'!H4:H5)>0,'Profit & Loss'!H12/SUM('Balance Sheet'!H4:H5),"") -> 0.31953267 | I23: =IF(SUM('Balance Sheet'!I4:I5)>0,'Profit & Loss'!I12/SUM('Balance Sheet'!I4:I5),"") -> 0.29770984 | ... K23: =IF(SUM('Balance Sheet'!K4:K5)>0,'Profit & Loss'!K12/SUM('Balance Sheet'!K4:K5),"") -> 0.31706371
A24: Return on Capital Emp | C24: =IF((B4+B5+B6+C4+C5+C6)>0,('Profit & Loss'!C10+'Profit & Loss'!C9)*2/(B4+B5+B6+C4+C5+C6),"") -> 0.30275195 | D24: =IF((C4+C5+C6+D4+D5+D6)>0,('Profit & Loss'!D10+'Profit & Loss'!D9)*2/(C4+C5+C6+D4+D5+D6),"") -> 0.32402923 | E24: =IF((D4+D5+D6+E4+E5+E6)>0,('Profit & Loss'!E10+'Profit & Loss'!E9)*2/(D4+D5+D6+E4+E5+E6),"") -> 0.32847272 | F24: =IF((E4+E5+E6+F4+F5+F6)>0,('Profit & Loss'!F10+'Profit & Loss'!F9)*2/(E4+E5+E6+F4+F5+F6),"") -> 0.35349469 | G24: =IF((F4+F5+F6+G4+G5+G6)>0,('Profit & Loss'!G10+'Profit & Loss'!G9)*2/(F4+F5+F6+G4+G5+G6),"") -> 0.37304615 | H24: =IF((G4+G5+G6+H4+H5+H6)>0,('Profit & Loss'!H10+'Profit & Loss'!H9)*2/(G4+G5+G6+H4+H5+H6),"") -> 0.40850909 | I24: =IF((H4+H5+H6+I4+I5+I6)>0,('Profit & Loss'!I10+'Profit & Loss'!I9)*2/(H4+H5+H6+I4+I5+I6),"") -> 0.40468196 | J24: =IF((I4+I5+I6+J4+J5+J6)>0,('Profit & Loss'!J10+'Profit & Loss'!J9)*2/(I4+I5+I6+J4+J5+J6),"") -> 0.37925394 | K24: =IF((J4+J5+J6+K4+K5+K6)>0,('Profit & Loss'!K10+'Profit & Loss'!K9)*2/(J4+J5+J6+K4+K5+K6),"") -> 0.39220082

Sheet Quarters
A1: ='Profit & Loss'!A1 -> INFOSYS LTD | E1: UPDATE | J1: SCREENER.IN
A3: Narration | B3: ='Data Sheet'!B41 -> 45382 | C3: ='Data Sheet'!C41 -> 45473 | D3: ='Data Sheet'!D41 -> 45565 | E3: ='Data Sheet'!E41 -> 45657 | F3: ='Data Sheet'!F41 -> 45747 | G3: ='Data Sheet'!G41 -> 45838 | H3: ='Data Sheet'!H41 -> 45930 | I3: ='Data Sheet'!I41 -> 46022 | ... K3: ='Data Sheet'!K41 -> 46203
A4: Sales | B4: ='Data Sheet'!B42 -> 37923 | C4: ='Data Sheet'!C42 -> 39315 | D4: ='Data Sheet'!D42 -> 40986 | E4: ='Data Sheet'!E42 -> 41764 | F4: ='Data Sheet'!F42 -> 40925 | G4: ='Data Sheet'!G42 -> 42279 | H4: ='Data Sheet'!H42 -> 44490 | I4: ='Data Sheet'!I42 -> 45479 | ... K4: ='Data Sheet'!K42 -> 48211
A5: Expenses | B5: ='Data Sheet'!B43 -> 29139 | C5: ='Data Sheet'!C43 -> 29878 | D5: ='Data Sheet'!D43 -> 31177 | E5: ='Data Sheet'!E43 -> 31649 | F5: ='Data Sheet'!F43 -> 31051 | G5: ='Data Sheet'!G43 -> 32336 | H5: ='Data Sheet'!H43 -> 33955 | I5: ='Data Sheet'!I43 -> 34845 | ... K5: ='Data Sheet'!K43 -> 36802
A6: Operating Profit | B6: ='Data Sheet'!B50 -> 8784 | C6: ='Data Sheet'!C50 -> 9437 | D6: ='Data Sheet'!D50 -> 9809 | E6: ='Data Sheet'!E50 -> 10115 | F6: ='Data Sheet'!F50 -> 9874 | G6: ='Data Sheet'!G50 -> 9943 | H6: ='Data Sheet'!H50 -> 10535 | I6: ='Data Sheet'!I50 -> 10634 | ... K6: ='Data Sheet'!K50 -> 11409
A7: Other Income | B7: ='Data Sheet'!B44 -> 2729 | C7: ='Data Sheet'!C44 -> 838 | D7: ='Data Sheet'!D44 -> 712 | E7: ='Data Sheet'!E44 -> 859 | F7: ='Data Sheet'!F44 -> 1190 | G7: ='Data Sheet'!G44 -> 1042 | H7: ='Data Sheet'!H44 -> 982 | I7: ='Data Sheet'!I44 -> -150 | ... K7: ='Data Sheet'!K44 -> 984
A8: Depreciation | B8: ='Data Sheet'!B45 -> 1163 | C8: ='Data Sheet'!C45 -> 1149 | D8: ='Data Sheet'!D45 -> 1160 | E8: ='Data Sheet'!E45 -> 1203 | F8: ='Data Sheet'!F45 -> 1299 | G8: ='Data Sheet'!G45 -> 1140 | H8: ='Data Sheet'!H45 -> 1182 | I8: ='Data Sheet'!I45 -> 1155 | ... K8: ='Data Sheet'!K45 -> 1246
A9: Interest | B9: ='Data Sheet'!B46 -> 110 | C9: ='Data Sheet'!C46 -> 105 | D9: ='Data Sheet'!D46 -> 108 | E9: ='Data Sheet'!E46 -> 101 | F9: ='Data Sheet'!F46 -> 102 | G9: ='Data Sheet'!G46 -> 105 | H9: ='Data Sheet'!H46 -> 106 | I9: ='Data Sheet'!I46 -> 100 | ... K9: ='Data Sheet'!K46 -> 119
A10: Profit before tax | B10: ='Data Sheet'!B47 -> 10240 | C10: ='Data Sheet'!C47 -> 9021 | D10: ='Data Sheet'!D47 -> 9253 | E10: ='Data Sheet'!E47 -> 9670 | F10: ='Data Sheet'!F47 -> 9663 | G10: ='Data Sheet'!G47 -> 9740 | H10: ='Data Sheet'!H47 -> 10229 | I10: ='Data Sheet'!I47 -> 9229 | ... K10: ='Data Sheet'!K47 -> 11028
A11: Tax | B11: ='Data Sheet'!B48 -> 2265 | C11: ='Data Sheet'!C48 -> 2647 | D11: ='Data Sheet'!D48 -> 2737 | E11: ='Data Sheet'!E48 -> 2848 | F11: ='Data Sheet'!F48 -> 2625 | G11: ='Data Sheet'!G48 -> 2816 | H11: ='Data Sheet'!H48 -> 2854 | I11: ='Data Sheet'!I48 -> 2563 | ... K11: ='Data Sheet'!K48 -> 3253
A12: Net profit | B12: ='Data Sheet'!B49 -> 7969 | C12: ='Data Sheet'!C49 -> 6368 | D12: ='Data Sheet'!D49 -> 6506 | E12: ='Data Sheet'!E49 -> 6806 | F12: ='Data Sheet'!F49 -> 7033 | G12: ='Data Sheet'!G49 -> 6921 | H12: ='Data Sheet'!H49 -> 7364 | I12: ='Data Sheet'!I49 -> 6654 | ... K12: ='Data Sheet'!K49 -> 7769
A14: OPM | B14: =IF(B4>0,B6/B4,"") -> 0.23162724 | C14: =IF(C4>0,C6/C4,"") -> 0.24003561 | D14: =IF(D4>0,D6/D4,"") -> 0.23932562 | E14: =IF(E4>0,E6/E4,"") -> 0.24219423 | F14: =IF(F4>0,F6/F4,"") -> 0.24127062 | G14: =IF(G4>0,G6/G4,"") -> 0.23517586 | H14: =IF(H4>0,H6/H4,"") -> 0.23679479 | I14: =IF(I4>0,I6/I4,"") -> 0.2338222 | ... K14: =IF(K4>0,K6/K4,"") -> 0.23664724

Sheet Common Size Statement
B7: ="Common Size Income Statement"&" "&"- "&'Data Sheet'!$B$1 -> Common Size Income Statement - INFOSYS LTD
B9: Particulars | C9: ='Data Sheet'!B16 -> 42825 | D9: ='Data Sheet'!C16 -> 43190 | E9: ='Data Sheet'!D16 -> 43555 | F9: ='Data Sheet'!E16 -> 43921 | G9: ='Data Sheet'!F16 -> 44286 | H9: ='Data Sheet'!G16 -> 44651 | I9: ='Data Sheet'!H16 -> 45016 | J9: ='Data Sheet'!I16 -> 45382 | ... L9: ='Data Sheet'!K16 -> 46112
B11: ='Data Sheet'!A17 -> Sales | C11: ='Data Sheet'!B17/'Data Sheet'!B$17 -> 1 | D11: ='Data Sheet'!C17/'Data Sheet'!C$17 -> 1 | E11: ='Data Sheet'!D17/'Data Sheet'!D$17 -> 1 | F11: ='Data Sheet'!E17/'Data Sheet'!E$17 -> 1 | G11: ='Data Sheet'!F17/'Data Sheet'!F$17 -> 1 | H11: ='Data Sheet'!G17/'Data Sheet'!G$17 -> 1 | I11: ='Data Sheet'!H17/'Data Sheet'!H$17 -> 1 | J11: ='Data Sheet'!I17/'Data Sheet'!I$17 -> 1 | ... L11: ='Data Sheet'!K17/'Data Sheet'!K$17 -> 1
B12: ='Data Sheet'!A18 -> Raw Material Cost | C12: ='Data Sheet'!B18/'Data Sheet'!B$17 -> 0 | D12: ='Data Sheet'!C18/'Data Sheet'!C$17 -> 0 | E12: ='Data Sheet'!D18/'Data Sheet'!D$17 -> 0 | F12: ='Data Sheet'!E18/'Data Sheet'!E$17 -> 0 | G12: ='Data Sheet'!F18/'Data Sheet'!F$17 -> 0 | H12: ='Data Sheet'!G18/'Data Sheet'!G$17 -> 0 | I12: ='Data Sheet'!H18/'Data Sheet'!H$17 -> 0 | J12: ='Data Sheet'!I18/'Data Sheet'!I$17 -> 0 | ... L12: ='Data Sheet'!K18/'Data Sheet'!K$17 -> 0
B13: ='Data Sheet'!A19 -> Change in Inventory | C13: ='Data Sheet'!B19/'Data Sheet'!B$17 -> 0 | D13: ='Data Sheet'!C19/'Data Sheet'!C$17 -> 0 | E13: ='Data Sheet'!D19/'Data Sheet'!D$17 -> 0 | F13: ='Data Sheet'!E19/'Data Sheet'!E$17 -> 0 | G13: ='Data Sheet'!F19/'Data Sheet'!F$17 -> 0 | H13: ='Data Sheet'!G19/'Data Sheet'!G$17 -> 0 | I13: ='Data Sheet'!H19/'Data Sheet'!H$17 -> 0 | J13: ='Data Sheet'!I19/'Data Sheet'!I$17 -> 0 | ... L13: ='Data Sheet'!K19/'Data Sheet'!K$17 -> 0
B14: ='Data Sheet'!A20 -> Power and Fuel | C14: ='Data Sheet'!B20/'Data Sheet'!B$17 -> 0.0033292448 | D14: ='Data Sheet'!C20/'Data Sheet'!C$17 -> 0.0029352542 | E14: ='Data Sheet'!D20/'Data Sheet'!D$17 -> 0.0026731176 | F14: ='Data Sheet'!E20/'Data Sheet'!E$17 -> 0.0025222764 | G14: ='Data Sheet'!F20/'Data Sheet'!F$17 -> 0.0014232821 | H14: ='Data Sheet'!G20/'Data Sheet'!G$17 -> 0.0010851604 | I14: ='Data Sheet'!H20/'Data Sheet'!H$17 -> 0.0011991797 | J14: ='Data Sheet'!I20/'Data Sheet'!I$17 -> 0.0012949828 | ... L14: ='Data Sheet'!K20/'Data Sheet'!K$17 -> 0.0012482508
B15: ='Data Sheet'!A21 -> Other Mfr. Exp | C15: ='Data Sheet'!B21/'Data Sheet'!B$17 -> 0.098008294 | D15: ='Data Sheet'!C21/'Data Sheet'!C$17 -> 0.10331528 | E15: ='Data Sheet'!D21/'Data Sheet'!D$17 -> 0.11977018 | F15: ='Data Sheet'!E21/'Data Sheet'!E$17 -> 0.12210461 | G15: ='Data Sheet'!F21/'Data Sheet'!F$17 -> 0.12739868 | H15: ='Data Sheet'!G21/'Data Sheet'!G$17 -> 0.17009068 | I15: ='Data Sheet'!H21/'Data Sheet'!H$17 -> 0.1794 | J15: ='Data Sheet'!I21/'Data Sheet'!I$17 -> 0.17697013 | ... L15: ='Data Sheet'!K21/'Data Sheet'!K$17 -> 0.18428212
B16: ='Data Sheet'!A22 -> Employee Cost | C16: ='Data Sheet'!B22/'Data Sheet'!B$17 -> 0.55004089 | D16: ='Data Sheet'!C22/'Data Sheet'!C$17 -> 0.55162928 | E16: ='Data Sheet'!D22/'Data Sheet'!D$17 -> 0.54820683 | F16: ='Data Sheet'!E22/'Data Sheet'!E$17 -> 0.56057318 | G16: ='Data Sheet'!F22/'Data Sheet'!F$17 -> 0.5528605 | H16: ='Data Sheet'!G22/'Data Sheet'!G$17 -> 0.52611373 | I16: ='Data Sheet'!H22/'Data Sheet'!H$17 -> 0.53400288 | J16: ='Data Sheet'!I22/'Data Sheet'!I$17 -> 0.53774972 | ... L16: ='Data Sheet'!K22/'Data Sheet'!K$17 -> 0.53239295
B17: ='Data Sheet'!A23 -> Selling and admin | C17: ='Data Sheet'!B23/'Data Sheet'!B$17 -> 0.066935343 | D17: ='Data Sheet'!C23/'Data Sheet'!C$17 -> 0.065015173 | E17: ='Data Sheet'!D23/'Data Sheet'!D$17 -> 0.067166616 | F17: ='Data Sheet'!E23/'Data Sheet'!E$17 -> 0.059201903 | G17: ='Data Sheet'!F23/'Data Sheet'!F$17 -> 0.031789951 | H17: ='Data Sheet'!G23/'Data Sheet'!G$17 -> 0.035391028 | I17: ='Data Sheet'!H23/'Data Sheet'!H$17 -> 0.03611166 | J17: ='Data Sheet'!I23/'Data Sheet'!I$17 -> 0.037125008 | ... L17: ='Data Sheet'!K23/'Data Sheet'!K$17 -> 0.037973692
B18: ='Data Sheet'!A24 -> Other Expenses | C18: ='Data Sheet'!B24/'Data Sheet'!B$17 -> 0.01003154 | D18: ='Data Sheet'!C24/'Data Sheet'!C$17 -> 0.01020958 | E18: ='Data Sheet'!D24/'Data Sheet'!D$17 -> 0.018215906 | F18: ='Data Sheet'!E24/'Data Sheet'!E$17 -> 0.010342435 | G18: ='Data Sheet'!F24/'Data Sheet'!F$17 -> 0.0089477665 | H18: ='Data Sheet'!G24/'Data Sheet'!G$17 -> 0.0084346561 | I18: ='Data Sheet'!H24/'Data Sheet'!H$17 -> 0.0099272997 | J18: ='Data Sheet'!I24/'Data Sheet'!I$17 -> 0.0098262511 | ... L18: ='Data Sheet'!K24/'Data Sheet'!K$17 -> 0.0074391268
B19: ='Data Sheet'!A25 -> Other Income | C19: ='Data Sheet'!B25/'Data Sheet'!B$17 -> 0.04453595 | D19: ='Data Sheet'!C25/'Data Sheet'!C$17 -> 0.046949888 | E19: ='Data Sheet'!D25/'Data Sheet'!D$17 -> 0.034859389 | F19: ='Data Sheet'!E25/'Data Sheet'!E$17 -> 0.030873104 | G19: ='Data Sheet'!F25/'Data Sheet'!F$17 -> 0.021906601 | H19: ='Data Sheet'!G25/'Data Sheet'!G$17 -> 0.018866994 | I19: ='Data Sheet'!H25/'Data Sheet'!H$17 -> 0.01840332 | J19: ='Data Sheet'!I25/'Data Sheet'!I$17 -> 0.030656602 | ... L19: ='Data Sheet'!K25/'Data Sheet'!K$17 -> 0.01697733
B20: ='Data Sheet'!A26 -> Depreciation | C20: ='Data Sheet'!B26/'Data Sheet'!B$17 -> 0.024867122 | D20: ='Data Sheet'!C26/'Data Sheet'!C$17 -> 0.026417288 | E20: ='Data Sheet'!D26/'Data Sheet'!D$17 -> 0.024324161 | F20: ='Data Sheet'!E26/'Data Sheet'!E$17 -> 0.031864392 | G20: ='Data Sheet'!F26/'Data Sheet'!F$17 -> 0.032516522 | H20: ='Data Sheet'!G26/'Data Sheet'!G$17 -> 0.028575891 | I20: ='Data Sheet'!H26/'Data Sheet'!H$17 -> 0.028787125 | J20: ='Data Sheet'!I26/'Data Sheet'!I$17 -> 0.030441856 | ... L20: ='Data Sheet'!K26/'Data Sheet'!K$17 -> 0.027439127
B21: ='Data Sheet'!A27 -> Interest | C21: ='Data Sheet'!B27/'Data Sheet'!B$17 -> 0 | D21: ='Data Sheet'!C27/'Data Sheet'!C$17 -> 0 | E21: ='Data Sheet'!D27/'Data Sheet'!D$17 -> 0 | F21: ='Data Sheet'!E27/'Data Sheet'!E$17 -> 0.0018724323 | G21: ='Data Sheet'!F27/'Data Sheet'!F$17 -> 0.0019408392 | H21: ='Data Sheet'!G27/'Data Sheet'!G$17 -> 0.0016441825 | I21: ='Data Sheet'!H27/'Data Sheet'!H$17 -> 0.0019350399 | J21: ='Data Sheet'!I27/'Data Sheet'!I$17 -> 0.003058502 | ... L21: ='Data Sheet'!K27/'Data Sheet'!K$17 -> 0.0023285754
